File: ir+dsc_data/DSC/FA3 Ar DSC form.txt
Time (min);Temperature (°C);Weight (mg);Heat Flow (mW);Temperature Difference (°C);Temperature Difference (µV);Sample Purge Flow (mL/min)
.004333333;26.69563;2.084347;14.69428;0.7777957;4.932384;100.0224
0.06266666;26.72680;2.085035;14.69856;0.7780066;4.934144;99.91386
0.1293333;26.77785;2.084994;14.71105;0.7788082;4.939987;100.0429
0.1960000;26.84422;2.084885;14.72239;0.7793860;4.944725;100.0135
0.2626667;26.94293;2.084988;14.73065;0.7795019;4.947024;99.99830
0.3293334;27.08384;2.084910;14.72856;0.7784312;4.942502;100.0410
0.3960000;27.25052;2.085235;14.71654;0.7762375;4.931489;100.0417
0.4626666;27.48434;2.084774;14.69360;0.7727402;4.913062;99.97176
0.5293334;27.75245;2.084783;14.65477;0.7674805;4.884346;99.92147
0.5960000;28.06665;2.084786;14.60036;0.7605339;4.845664;100.0122
0.6626668;28.43800;2.084579;14.52700;0.7515994;4.795082;99.96386
0.7293334;28.84237;2.084635;14.43948;0.7410816;4.735162;99.99094
0.7960000;29.30332;2.084122;14.33573;0.7288337;4.664833;100.0261
0.8626668;29.80524;2.083642;14.21525;0.7148535;4.583918;100.0355
0.9293334;30.35278;2.083428;14.07971;0.6993054;4.493355;100.0512
0.9960000;30.92869;2.083056;13.93244;0.6825128;4.395074;99.96203
1.062667;31.55072;2.082524;13.77282;0.6644806;4.288902;99.99384
1.129334;32.19026;2.082125;13.60181;0.6453134;4.175404;99.95995
1.196000;32.86152;2.081742;13.42692;0.6257222;4.058966;100.0354
1.262667;33.55748;2.081126;13.24434;0.6054026;3.937526;100.0092
1.329334;34.26906;2.080535;13.05427;0.5844024;3.811272;99.97319
1.396000;34.99391;2.079904;12.86065;0.5630980;3.682537;99.99824
1.462666;35.73370;2.079262;12.66277;0.5414858;3.551142;100.0500
1.529334;36.47416;2.078613;12.46803;0.5201663;3.421074;99.97053
1.596000;37.22708;2.077888;12.26892;0.4985639;3.288410;100.0123
1.662666;37.98064;2.077139;12.07010;0.4770856;3.155796;100.0153
1.729334;38.73142;2.076440;11.87331;0.4558848;3.024240;99.97901
1.796000;39.48844;2.075736;11.68056;0.4352072;2.895049;99.96020
1.862666;40.23003;2.074826;11.48688;0.4146320;2.765320;99.99231
1.929334;40.97914;2.074092;11.30176;0.3949053;2.640485;100.0023
1.996000;41.71441;2.073180;11.11939;0.3755282;2.517290;99.97801
2.062666;42.44208;2.072422;10.94388;0.3568741;2.398213;100.0157
2.129333;43.17000;2.071486;10.77169;0.3386250;2.281186;99.98358
2.196000;43.88250;2.070633;10.60322;0.3207936;2.166348;100.0152
2.262666;44.59600;2.069781;10.43930;0.3034832;2.054373;100.0110
2.329333;45.29044;2.068955;10.27978;0.2866436;1.944995;99.96916
2.396000;45.98736;2.068108;10.12977;0.2707236;1.841261;99.97926
2.462666;46.66496;2.067194;9.983075;0.2551613;1.739442;99.98150
2.529333;47.33334;2.066201;9.838179;0.2398954;1.639075;99.96001
2.596000;47.99890;2.065395;9.704025;0.2256224;1.544984;99.98608
2.662666;48.67063;2.064414;9.572486;0.2116192;1.452316;99.99128
2.729334;49.32224;2.063498;9.446044;0.1981212;1.362670;99.99402
2.796000;49.96926;2.062523;9.325324;0.1851972;1.276528;100.0465
2.862666;50.60930;2.061508;9.207675;0.1726067;1.192279;100.0303
2.929334;51.24982;2.060653;9.090546;0.1601413;1.108503;100.0370
2.996000;51.88481;2.059756;8.982594;0.1484526;1.029763;99.98178
3.062666;52.51086;2.058794;8.873986;0.1367988;0.9508960;100.0188
3.129333;53.13982;2.057767;8.769953;0.1255751;0.8746801;99.98876
3.196000;53.76814;2.056728;8.668668;0.1146276;0.8000634;99.95749
3.262666;54.38981;2.055763;8.572862;0.1041750;0.7285880;99.93105
3.329334;55.01478;2.054762;8.477208;0.09378374;0.6572419;100.0091
3.396000;55.63032;2.053740;8.382609;0.08351772;0.5864809;99.96691
3.462666;56.24602;2.052630;8.290888;0.07354205;0.5174629;100.0583
3.529334;56.86754;2.051556;8.197418;0.06346044;0.4474194;100.0148
3.596000;57.49006;2.050383;8.110232;0.05392064;0.3809174;99.96064
3.662666;58.11048;2.049388;8.020922;0.04421124;0.3129556;99.98761
3.729334;58.73310;2.048270;7.928552;0.03433635;0.2435358;100.0222
3.796000;59.36039;2.047134;7.842390;0.02497448;0.1774760;99.98478
3.862666;59.98332;2.045867;7.756739;0.01567834;0.1116127;100.0377
3.929334;60.61693;2.044701;7.668448;.006191956;0.04415113;100.0299
3.996000;61.23718;2.043521;7.583594;-2.9825E-3;-.02132851;99.96254
4.062667;61.86851;2.042181;7.498478;-.01214304;-.08694670;100.0227
4.129334;62.51003;2.041090;7.416562;-.02104503;-0.1509511;99.99392
4.196000;63.12976;2.039795;7.332272;-.03009822;-0.2162750;99.98851
4.262666;63.77454;2.038524;7.247232;-.03916934;-0.2819643;100.0355
4.329334;64.40386;2.037284;7.162274;-.04823084;-0.3478279;99.99397
4.396000;65.04356;2.035935;7.077206;-.05724880;-0.4136101;100.0110
4.462666;65.68160;2.034540;6.994556;-.06608069;-0.4782944;99.94884
4.529333;66.32782;2.033165;6.909551;-.07504230;-0.5441470;100.0188
4.596000;66.96936;2.031788;6.827288;-.08378482;-0.6086551;99.99019
4.662666;67.61381;2.030370;6.746028;-.09241798;-0.6725991;100.0076
4.729334;68.26089;2.029030;6.665228;-0.1009788;-0.7362442;100.0022
4.796000;68.90669;2.027588;6.584586;-0.1095266;-0.8000384;100.0506
4.862666;69.55480;2.026285;6.507030;-0.1177890;-0.8619625;99.99134
4.929333;70.20412;2.024927;6.431164;-0.1259136;-0.9231112;99.99119
4.996000;70.85634;2.023433;6.353850;-0.1341145;-0.9850369;99.95415
5.062667;71.51311;2.021970;6.280124;-0.1420222;-1.045033;100.0026
5.129334;72.16554;2.020582;6.205093;-0.1500153;-1.105886;100.0663
5.196000;72.81884;2.019188;6.130863;-0.1579128;-1.166244;100.0432
5.262666;73.46680;2.017822;6.059810;-0.1655249;-1.224688;99.98528
5.329334;74.12128;2.016366;5.990046;-0.1730213;-1.282487;99.94358
5.396000;74.77816;2.014922;5.922682;-0.1803150;-1.338992;99.99332
5.462666;75.43648;2.013575;5.856063;-0.1875411;-1.395204;99.99429
5.529332;76.09264;2.012248;5.791363;-0.1945941;-1.450322;99.96860
5.596000;76.74874;2.010795;5.731680;-0.2012524;-1.502689;100.0513
5.662666;77.41434;2.009414;5.667530;-0.2082124;-1.557490;99.97280
5.729334;78.06694;2.008099;5.611399;-0.2145618;-1.607915;100.0271
5.796000;78.72199;2.006749;5.553488;-0.2210072;-1.659220;100.0234
5.862666;79.38806;2.005356;5.494808;-0.2275012;-1.710976;100.0001
5.929332;80.04524;2.004007;5.441943;-0.2335717;-1.759546;99.97801
5.996000;80.70788;2.002856;5.395859;-0.2391262;-1.804364;100.0237
6.062668;81.35766;2.001514;5.347596;-0.2448228;-1.850394;100.0323
6.129334;82.02460;2.000262;5.298297;-0.2505706;-1.896941;100.0127
6.196000;82.68022;1.998850;5.255415;-0.2558317;-1.939948;100.0058
6.262666;83.33371;1.997567;5.211343;-0.2611577;-1.983571;99.97351
6.329334;83.99140;1.996432;5.170000;-0.2662556;-2.025572;100.0112
6.396000;84.65094;1.995272;5.130258;-0.2712356;-2.066827;100.0124
6.462666;85.31554;1.994157;5.092404;-0.2760756;-2.107160;100.0303
6.529334;85.97134;1.992990;5.054978;-0.2808610;-2.147185;100.0555
6.596000;86.63155;1.991705;5.019709;-0.2854644;-2.185916;100.0494
6.662668;87.29361;1.990502;4.988076;-0.2897887;-2.222623;100.0149
6.729334;87.95338;1.989343;4.957936;-0.2939934;-2.258524;99.96556
6.796000;88.60951;1.988294;4.926403;-0.2982871;-2.295216;99.98658
6.862666;89.27215;1.987138;4.899741;-0.3022183;-2.329227;99.99630
6.929334;89.93225;1.986138;4.869228;-0.3064133;-2.365372;100.0188
6.996000;90.58525;1.985185;4.842736;-0.3103011;-2.399236;99.97308
7.062668;91.24934;1.984088;4.818706;-0.3140023;-2.431758;99.99478
7.129334;91.90697;1.982973;4.795463;-0.3176306;-2.463800;100.0286
7.196000;92.56997;1.982036;4.768877;-0.3214888;-2.497718;100.0204
7.262666;93.22644;1.980983;4.747979;-0.3249314;-2.528508;99.98145
7.329334;93.88634;1.979943;4.724381;-0.3285561;-2.560803;99.97169
7.396000;94.54042;1.979080;4.706864;-0.3317306;-2.589664;100.0523
7.462666;95.20194;1.978084;4.687195;-0.3350444;-2.619684;100.0345
7.529334;95.86712;1.977133;4.673002;-0.3379719;-2.646791;100.1720
7.596000;96.52466;1.976222;4.654466;-0.3411888;-2.676221;100.0714
7.662668;97.18774;1.975238;4.636856;-0.3443376;-2.705214;99.96132
7.729334;97.84819;1.974401;4.619580;-0.3474542;-2.734032;99.95816
7.796000;98.51460;1.973366;4.606048;-0.3502991;-2.760795;100.0401
7.862666;99.16949;1.972563;4.587996;-0.3534555;-2.790024;99.99320
7.929334;99.82891;1.971687;4.572113;-0.3564808;-2.818002;100.0465
7.996000;100.4973;1.970782;4.560756;-0.3591969;-2.843546;99.95428
8.062668;101.1568;1.969916;4.546414;-0.3621137;-2.870739;99.96941
8.129334;101.8190;1.969086;4.532090;-0.3650137;-2.897847;99.97131
8.196000;102.4797;1.968172;4.520266;-0.3677412;-2.923677;100.0124
8.262666;103.1462;1.967292;4.505410;-0.3706716;-2.951178;100.0085
8.329334;103.8134;1.966579;4.497678;-0.3731029;-2.974782;100.0213
8.396000;104.4783;1.965794;4.484766;-0.3758848;-3.001233;100.0238
8.462666;105.1369;1.964921;4.472228;-0.3786306;-3.027454;100.0049
8.529334;105.7971;1.964017;4.461697;-0.3812264;-3.052528;100.0256
8.596000;106.4607;1.963299;4.450412;-0.3838641;-3.077992;99.95441
8.662666;107.1251;1.962483;4.441269;-0.3863510;-3.102316;100.0378
8.729332;107.7862;1.961682;4.431458;-0.3888776;-3.127016;99.96259
8.795999;108.4530;1.960872;4.420234;-0.3914964;-3.152522;100.0400
8.862668;109.1159;1.960142;4.410244;-0.3940176;-3.177287;99.98012
8.929334;109.7806;1.959406;4.403210;-0.3963410;-3.200543;99.97781
8.996001;110.4502;1.958668;4.395669;-0.3986851;-3.224002;100.0138
9.062668;111.1098;1.957947;4.387362;-0.4010694;-3.247825;99.99038
9.129334;111.7746;1.957200;4.379234;-0.4034526;-3.271738;99.95697
9.196000;112.4432;1.956439;4.371489;-0.4057922;-3.295325;99.95626
9.262666;113.1086;1.955696;4.366933;-0.4079122;-3.317192;100.0574
9.329334;113.7699;1.954988;4.359472;-0.4102153;-3.340575;99.99425
9.396000;114.4350;1.954219;4.354330;-0.4123602;-3.362735;100.0160
9.462666;115.0973;1.953497;4.345532;-0.4147430;-3.386875;100.0009
9.529334;115.7662;1.952883;4.337358;-0.4170808;-3.410709;99.99859
9.596000;116.4320;1.952127;4.334762;-0.4190272;-3.431379;100.0437
9.662666;117.0915;1.951415;4.328457;-0.4212238;-3.454152;99.99744
9.729332;117.7661;1.950709;4.324758;-0.4232518;-3.475633;99.95642
9.795999;118.4288;1.950037;4.321660;-0.4252235;-3.496669;100.0064
9.862668;119.0954;1.949017;4.315030;-0.4274278;-3.519617;100.0236
9.929334;119.7567;1.948880;4.310735;-0.4295078;-3.541327;100.0487
9.996001;120.4254;1.947783;4.307170;-0.4315396;-3.562554;99.94055
10.06267;121.0907;1.947283;4.304800;-0.4334922;-3.583186;99.99118
10.12933;121.7593;1.946894;4.302994;-0.4354074;-3.603563;99.98272
10.19600;122.4194;1.946236;4.298539;-0.4374893;-3.625344;99.95934
10.26267;123.0877;1.945609;4.295971;-0.4394320;-3.645995;99.99139
10.32933;123.7547;1.944844;4.294276;-0.4413164;-3.666216;99.96610
10.39600;124.4134;1.944272;4.292432;-0.4432107;-3.686570;99.97895
10.46267;125.0859;1.943727;4.293119;-0.4449268;-3.705469;100.0092
10.52934;125.7435;1.942998;4.290634;-0.4468532;-3.726163;99.97882
10.59600;126.4090;1.942507;4.290728;-0.4485921;-3.745304;100.0039
10.66266;127.0694;1.941885;4.290936;-0.4503228;-3.764424;100.0327
10.72933;127.7389;1.941315;4.292739;-0.4519453;-3.782677;99.96818
10.79600;128.4077;1.940704;4.296238;-0.4534574;-3.800059;100.0388
10.86267;129.0756;1.940097;4.297076;-0.4551446;-3.818946;100.0376
10.92934;129.7346;1.939528;4.298288;-0.4567971;-3.837562;100.0304
10.99600;130.4031;1.938994;4.301800;-0.4582886;-3.854846;100.0123
11.06267;131.0702;1.938500;4.306154;-0.4597234;-3.871690;100.0094
11.12934;131.7286;1.937879;4.308442;-0.4612946;-3.889723;99.95659
11.19600;132.3878;1.937297;4.309955;-0.4629044;-3.908090;100.0058
11.26266;133.0588;1.936760;4.309161;-0.4646584;-3.927701;100.0500
11.32934;133.7214;1.936180;4.312620;-0.4661467;-3.945148;99.99374
11.39600;134.3881;1.935737;4.318506;-0.4674620;-3.961136;99.97944
11.46266;135.0507;1.935128;4.322237;-0.4689122;-3.978284;100.0275
11.52934;135.7209;1.934644;4.328114;-0.4702265;-3.994332;100.0304
11.59600;136.3852;1.934205;4.332246;-0.4716519;-4.011354;99.97866
11.66266;137.0498;1.933636;4.338168;-0.4729561;-4.027370;99.99328
11.72933;137.7159;1.932979;4.344346;-0.4742359;-4.043193;99.97234
11.79600;138.3789;1.932620;4.350025;-0.4755448;-4.059292;99.98469
11.86267;139.0407;1.932127;4.356590;-0.4768004;-4.074949;99.99158
11.92934;139.7042;1.931623;4.364604;-0.4779854;-4.089735;100.0416
11.99600;140.3776;1.931093;4.373266;-0.4791448;-4.104200;100.0350
12.06267;141.0378;1.930609;4.381141;-0.4803469;-4.119038;100.0165
12.12934;141.7082;1.930121;4.387910;-0.4816246;-4.134566;100.0277
12.19600;142.3685;1.929511;4.396208;-0.4828086;-4.149332;99.98859
12.26266;143.0349;1.929172;4.404436;-0.4839780;-4.163952;99.98843
12.32934;143.6997;1.928736;4.411774;-0.4852064;-4.179116;100.0236
12.39600;144.3636;1.928244;4.421840;-0.4862606;-4.192810;100.0304
12.46266;145.0284;1.927732;4.433520;-0.4872066;-4.205588;99.96113
12.52934;145.6980;1.927312;4.442406;-0.4883348;-4.219969;99.95470
12.59600;146.3653;1.926852;4.452032;-0.4894194;-4.234012;99.96496
12.66266;147.0343;1.926462;4.459834;-0.4906070;-4.248934;99.98509
12.72933;147.6962;1.926040;4.472310;-0.4914966;-4.261309;100.0092
12.79600;148.3641;1.925506;4.483688;-0.4924516;-4.274262;99.97675
12.86267;149.0269;1.924950;4.494354;-0.4934511;-4.287620;99.99381
12.92934;149.6981;1.924664;4.507660;-0.4942820;-4.299539;99.97284
12.99600;150.3689;1.924364;4.518646;-0.4952648;-4.312810;100.0477
13.06266;151.0333;1.923840;4.528416;-0.4963210;-4.326734;100.0022
13.12934;151.7012;1.923345;4.540816;-0.4971989;-4.339100;100.0042
13.19600;152.3729;1.922997;4.553989;-0.4980392;-4.351192;99.96953
13.26266;153.0344;1.922608;4.569938;-0.4986977;-4.361702;100.0052
13.32934;153.7045;1.922211;4.584190;-0.4994572;-4.373094;99.95780
13.39600;154.3764;1.921845;4.595062;-0.5004348;-4.386424;100.0122
13.46266;155.0386;1.921358;4.607910;-0.5012776;-4.398570;100.0141
13.52934;155.7052;1.921034;4.620806;-0.5021146;-4.410678;100.0236
13.59600;156.3721;1.920597;4.633996;-0.5029334;-4.422648;99.97609
13.66266;157.0352;1.920288;4.649006;-0.5036360;-4.433614;99.98066
13.72934;157.7017;1.919839;4.660606;-0.5045459;-4.446400;99.96699
13.79600;158.3714;1.919379;4.677720;-0.5051140;-4.456211;99.99074
13.86267;159.0359;1.919042;4.691800;-0.5058704;-4.467665;99.99913
13.92934;159.7022;1.918690;4.709066;-0.5064522;-4.477344;99.97970
13.99600;160.3629;1.918400;4.724422;-0.5071671;-4.488084;99.95819
14.06266;161.0270;1.917959;4.739804;-0.5078726;-4.498738;99.95663
14.12934;161.6939;1.917637;4.756485;-0.5084983;-4.508704;99.96238
14.19600;162.3586;1.917291;4.771783;-0.5092136;-4.519488;100.0151
14.26266;163.0286;1.916865;4.786334;-0.5099783;-4.530730;99.97839
14.32934;163.6958;1.916488;4.804623;-0.5105060;-4.539879;100.0302
14.39600;164.3627;1.916280;4.822476;-0.5110578;-4.549244;100.0251
14.46266;165.0247;1.915969;4.839952;-0.5116338;-4.558840;100.0377
14.52934;165.6914;1.915607;4.856646;-0.5122498;-4.568780;100.0092
14.59600;166.3626;1.915160;4.874864;-0.5127787;-4.577978;100.0113
14.66266;167.0281;1.914821;4.892210;-0.5133618;-4.587674;100.0260
14.72934;167.7005;1.914576;4.909236;-0.5139652;-4.597563;99.95869
14.79600;168.3602;1.914228;4.929361;-0.5143733;-4.605714;100.0452
14.86267;169.0308;1.913894;4.946793;-0.5149404;-4.615276;100.0148
14.92934;169.6950;1.913650;4.964794;-0.5154741;-4.624554;99.96553
14.99600;170.3591;1.913303;4.983262;-0.5159744;-4.633533;100.0283
15.06266;171.0244;1.912909;5.002844;-0.5164046;-4.641890;100.0261
15.12934;171.6878;1.912678;5.022432;-0.5168352;-4.650266;100.0100
15.19600;172.3571;1.912395;5.040961;-0.5173337;-4.659266;100.0341
15.26266;173.0218;1.912055;5.060540;-0.5177659;-4.667676;100.0119
15.32934;173.6915;1.911710;5.082907;-0.5180268;-4.674553;100.0262
15.39600;174.3577;1.911361;5.104166;-0.5183576;-4.682074;99.94699
15.46266;175.0242;1.911112;5.125708;-0.5186696;-4.689426;99.96919
15.52934;175.6922;1.910928;5.145694;-0.5190752;-4.697626;99.99950
15.59600;176.3564;1.910580;5.167378;-0.5193712;-4.704830;99.98094
15.66266;177.0214;1.910331;5.189754;-0.5196260;-4.711670;99.98201
15.72934;177.6923;1.909982;5.208541;-0.5201022;-4.720528;99.95519
15.79600;178.3568;1.909659;5.233150;-0.5202253;-4.726200;100.0272
15.86267;179.0245;1.909352;5.254444;-0.5205452;-4.733624;100.0060
15.92934;179.6903;1.909076;5.274639;-0.5209590;-4.741672;100.0385
15.99600;180.3529;1.908835;5.298105;-0.5211910;-4.747953;99.98628
16.06266;181.0241;1.908479;5.318962;-0.5215790;-4.755656;99.99784
16.12934;181.6924;1.908172;5.341436;-0.5218709;-4.762494;100.0146
16.19600;182.3567;1.907991;5.364117;-0.5221443;-4.769156;99.94425
16.26266;183.0228;1.907772;5.389580;-0.5222446;-4.774232;100.0086
16.32934;183.6867;1.907574;5.411287;-0.5225762;-4.781432;100.0509
16.39600;184.3537;1.907244;5.433830;-0.5228560;-4.788163;99.96991
16.46267;185.0216;1.907011;5.454589;-0.5232452;-4.795904;100.0174
16.52934;185.6823;1.906708;5.476279;-0.5235769;-4.803123;100.0516
16.59600;186.3502;1.906420;5.497138;-0.5239582;-4.810803;99.94981
16.66266;187.0167;1.906184;5.519446;-0.5242546;-4.817716;99.96314
16.72934;187.6861;1.905918;5.542340;-0.5245122;-4.824273;99.95322
16.79600;188.3493;1.905683;5.565790;-0.5247344;-4.830502;99.96438
16.86267;189.0172;1.905472;5.588820;-0.5249916;-4.837084;100.0027
16.92934;189.6823;1.905167;5.611466;-0.5252615;-4.843761;100.0333
16.99600;190.3497;1.904949;5.634458;-0.5255080;-4.850220;99.92931
17.06266;191.0200;1.904651;5.660270;-0.5255889;-4.855168;100.0084
17.12934;191.6824;1.904427;5.685098;-0.5257288;-4.860661;100.0165
17.19600;192.3521;1.904166;5.711810;-0.5257504;-4.865050;99.96156
17.26266;193.0188;1.903978;5.737526;-0.5258416;-4.870110;99.95082
17.32934;193.6861;1.903717;5.760738;-0.5260754;-4.876472;100.0527
17.39600;194.3509;1.903426;5.787048;-0.5261230;-4.881114;100.0298
17.46267;195.0161;1.903125;5.810088;-0.5263655;-4.887560;100.0349
17.52934;195.6828;1.902946;5.833080;-0.5266162;-4.894100;100.0210
17.59600;196.3486;1.902709;5.860787;-0.5265824;-4.897996;99.94772
17.66266;197.0147;1.902448;5.886993;-0.5266346;-4.902680;100.0411
17.72934;197.6831;1.902236;5.913644;-0.5266657;-4.907184;100.0384
17.79600;198.3528;1.902090;5.941038;-0.5266528;-4.911280;100.0062
17.86267;199.0168;1.901803;5.964366;-0.5268832;-4.917630;99.95985
17.92934;199.6918;1.901424;5.991568;-0.5269070;-4.921850;99.99535
17.99600;200.3503;1.901235;6.019348;-0.5270132;-4.926733;100.0614
18.06266;201.0121;1.900980;6.042839;-0.5270156;-4.930600;100.0034
18.12934;201.6780;1.900736;6.059124;-0.5270709;-4.934978;100.0363
18.19600;202.3541;1.900574;6.076911;-0.5270440;-4.938610;100.0050
18.26266;203.0215;1.900331;6.094060;-0.5270482;-4.942556;100.0327
18.32934;203.6914;1.900127;6.110308;-0.5271018;-4.946951;99.94438
18.39600;204.3590;1.899908;6.127315;-0.5271048;-4.950866;99.96969
18.46267;205.0264;1.899608;6.145746;-0.5270198;-4.953950;99.95906
18.52934;205.6931;1.899459;6.165782;-0.5268363;-4.956100;100.0228
18.59600;206.3603;1.899158;6.182165;-0.5268662;-4.960270;100.0314
18.66266;207.0299;1.898868;6.201988;-0.5266920;-4.962507;100.0492
18.72934;207.6995;1.898602;6.221613;-0.5265284;-4.964854;100.0235
18.79600;208.3722;1.898416;6.238638;-0.5265168;-4.968648;100.0145
18.86267;209.0429;1.898272;6.254989;-0.5265371;-4.972720;99.92992
18.92934;209.7061;1.898060;6.270644;-0.5265896;-4.977108;99.98605
18.99600;210.3785;1.897877;6.287674;-0.5265656;-4.980766;100.0229
19.06266;211.0439;1.897544;6.306804;-0.5264125;-4.983206;100.0276
19.12934;211.7183;1.897311;6.326863;-0.5262092;-4.985160;99.97950
19.19600;212.3772;1.897084;6.344438;-0.5261344;-4.988331;99.98621
19.26266;213.0485;1.896856;6.362455;-0.5260398;-4.991306;99.97931
19.32934;213.7212;1.896711;6.382634;-0.5258218;-4.993124;99.94536
19.39600;214.3839;1.896419;6.400342;-0.5257348;-4.996186;100.0188
19.46267;215.0600;1.896169;6.417398;-0.5256907;-4.999644;99.92528
19.52934;215.7208;1.895934;6.436557;-0.5255132;-5.001832;100.0297
19.59600;216.3883;1.895863;6.455276;-0.5253613;-5.004244;99.98863
19.66266;217.0589;1.895599;6.474220;-0.5251976;-5.006556;99.95188
19.72934;217.7290;1.895330;6.491843;-0.5251055;-5.009547;99.94731
19.79600;218.4000;1.894985;6.511706;-0.5248876;-5.011357;99.99955
19.86267;219.0661;1.894791;6.530710;-0.5247113;-5.013516;99.99852
19.92934;219.7324;1.894547;6.547380;-0.5246836;-5.016903;99.95952
19.99600;220.3945;1.894326;6.564470;-0.5246349;-5.020000;100.0891
20.06266;221.0613;1.894170;6.587594;-0.5242493;-5.019864;100.0017
20.12934;221.7290;1.894013;6.609326;-0.5239406;-5.020459;100.0130
20.19600;222.3934;1.893662;6.629770;-0.5237004;-5.021720;100.0327
20.26266;223.0597;1.893452;6.647207;-0.5236260;-5.024561;99.96160
20.32934;223.7358;1.893114;6.671455;-0.5231818;-5.023876;100.0212
20.39600;224.3976;1.892918;6.694736;-0.5227778;-5.023555;99.93969
20.46267;225.0677;1.892647;6.716359;-0.5224690;-5.024138;100.0396
20.52934;225.7355;1.892369;6.740512;-0.5220178;-5.023347;99.97978
20.59600;226.4016;1.892193;6.763141;-0.5216476;-5.023328;100.0215
20.66266;227.0633;1.891909;6.787085;-0.5212002;-5.022550;99.95970
20.72934;227.7269;1.891704;6.810055;-0.5208062;-5.022286;100.0101
20.79600;228.3964;1.891398;6.834179;-0.5203522;-5.021430;100.0106
20.86267;229.0633;1.891160;6.859189;-0.5198486;-5.020106;99.99520
20.92934;229.7356;1.890900;6.883960;-0.5193611;-5.018932;99.97774
20.99600;230.4000;1.890582;6.911165;-0.5187361;-5.016430;99.97712
21.06266;231.0694;1.890404;6.940795;-0.5179820;-5.012660;99.99132
21.12934;231.7356;1.890082;6.968276;-0.5173418;-5.009982;100.0284
21.19600;232.4064;1.889838;6.995902;-0.5166976;-5.007260;99.98832
21.26266;233.0674;1.889516;7.023628;-0.5160411;-5.004414;100.0154
21.32934;233.7391;1.889233;7.054781;-0.5152072;-4.999832;99.99400
21.39600;234.4065;1.889025;7.083966;-0.5144770;-4.996248;99.97062
21.46267;235.0756;1.888623;7.112988;-0.5137559;-4.992730;99.99701
21.52934;235.7409;1.888338;7.146770;-0.5127800;-4.986746;100.0298
21.59600;236.4068;1.887992;7.180089;-0.5118294;-4.980984;99.99788
21.66266;237.0814;1.887835;7.211716;-0.5109772;-4.976174;99.92188
21.72934;237.7490;1.887447;7.245796;-0.5099902;-4.970036;100.0672
21.79600;238.4148;1.887090;7.281128;-0.5089367;-4.963234;99.99699
21.86267;239.0828;1.886687;7.316412;-0.5078904;-4.956464;99.97407
21.92934;239.7532;1.886451;7.351209;-0.5068926;-4.949986;99.96476
21.99600;240.4226;1.885972;7.389278;-0.5057303;-4.941817;99.97071
22.06266;241.0880;1.885604;7.425378;-0.5046700;-4.934626;99.92294
22.12934;241.7556;1.885288;7.467844;-0.5032789;-4.924179;99.95766
22.19600;242.4242;1.884912;7.507556;-0.5020348;-4.915148;99.94349
22.26266;243.0932;1.884457;7.550132;-0.5006454;-4.904690;99.99503
22.32934;243.7609;1.884123;7.596897;-0.4990402;-4.892108;100.0094
22.39600;244.4316;1.883698;7.645043;-0.4973686;-4.878840;99.96366
22.46267;245.1004;1.883247;7.692164;-0.4957530;-4.866112;100.0265
22.52934;245.7681;1.882705;7.741190;-0.4940422;-4.852429;100.0062
22.59600;246.4338;1.882164;7.794350;-0.4921180;-4.836601;99.95149
22.66266;247.1039;1.881721;7.845169;-0.4903264;-4.822086;100.0330
22.72934;247.7673;1.881222;7.899307;-0.4883612;-4.805822;99.99812
22.79600;248.4431;1.880591;7.958379;-0.4861587;-4.787210;99.98618
22.86267;249.1140;1.880063;8.016466;-0.4840090;-4.769089;100.0003
22.92934;249.7838;1.879561;8.078370;-0.4816699;-4.749081;99.96046
22.99600;250.4518;1.878936;8.141369;-0.4792783;-4.728508;99.98005
23.06266;251.1180;1.878174;8.211700;-0.4765190;-4.704285;100.0254
23.12934;251.7917;1.877570;8.283438;-0.4737019;-4.679447;99.96664
23.19600;252.4605;1.876776;8.361676;-0.4705604;-4.651382;100.0211
23.26266;253.1310;1.876038;8.442009;-0.4673227;-4.622314;100.0150
23.32934;253.8005;1.875228;8.527801;-0.4638196;-4.590590;99.99436
23.39600;254.4716;1.874376;8.617242;-0.4601439;-4.557109;99.94851
23.46267;255.1455;1.873349;8.708749;-0.4563801;-4.522722;99.97535
23.52934;255.8142;1.872398;8.808890;-0.4521885;-4.484036;99.99039
23.59600;256.4871;1.871420;8.915155;-0.4477062;-4.442409;99.99269
23.66266;257.1582;1.870212;9.027722;-0.4429214;-4.397719;100.0031
23.72934;257.8295;1.868977;9.147968;-0.4377700;-4.349339;100.0187
23.79600;258.5012;1.867710;9.276528;-0.4322213;-4.296944;99.96192
23.86267;259.1780;1.866296;9.411895;-0.4263598;-4.241346;100.0296
23.92934;259.8516;1.864607;9.546239;-0.4205796;-4.186344;100.0065
23.99600;260.5256;1.862909;9.689318;-0.4143902;-4.127170;99.97944
24.06266;261.1939;1.861022;9.832678;-0.4082022;-4.067930;100.0037
24.12934;261.8619;1.858882;9.980816;-0.4017976;-4.006454;99.97636
24.19600;262.5414;1.856529;10.13081;-0.3953359;-3.944342;99.94556
24.26266;263.2151;1.853842;10.28012;-0.3889239;-3.882648;100.0207
24.32934;263.8870;1.850916;10.42609;-0.3826975;-3.822734;100.0101
24.39600;264.5638;1.847577;10.56831;-0.3766818;-3.764856;99.92801
24.46267;265.2326;1.843841;10.70510;-0.3709460;-3.709710;100.0138
24.52934;265.9046;1.839589;10.83482;-0.3655774;-3.658160;100.0364
24.59600;266.5787;1.834724;10.95624;-0.3606350;-3.610817;99.99285
24.66266;267.2464;1.829368;11.06634;-0.3562550;-3.569050;99.99776
24.72934;267.9173;1.823326;11.16027;-0.3526785;-3.535275;99.98755
24.79600;268.5887;1.816595;11.25437;-0.3491068;-3.501509;100.0057
24.86267;269.2564;1.809639;11.34905;-0.3455139;-3.467481;100.0340
24.92934;269.9265;1.802466;11.45915;-0.3411900;-3.426082;100.0388
24.99600;270.6047;1.795450;11.60192;-0.3353116;-3.369018;99.99295
25.06266;271.2783;1.788715;11.79879;-0.3268406;-3.285830;99.99830
25.12934;271.9568;1.782521;12.05794;-0.3154052;-3.172718;100.0232
25.19600;272.6367;1.777158;12.34364;-0.3027389;-3.047100;99.95695
25.26266;273.3126;1.772833;12.59481;-0.2917690;-2.938413;99.95772
25.32934;273.9834;1.769534;12.77590;-0.2841860;-2.863715;100.0034
25.39600;274.6575;1.766758;12.89899;-0.2794040;-2.817159;99.99765
25.46267;275.3240;1.764409;12.98424;-0.2764355;-2.788845;100.0133
25.52934;275.9909;1.762168;13.04561;-0.2746122;-2.772046;100.0284
25.59600;276.6558;1.760308;13.08622;-0.2737795;-2.765234;99.94697
25.66266;277.3222;1.758274;13.10670;-0.2739047;-2.768086;100.0689
25.72934;277.9841;1.756568;13.11984;-0.2743702;-2.774376;100.0171
25.79600;278.6492;1.754879;13.12516;-0.2752076;-2.784440;100.0438
25.86267;279.3152;1.753098;13.11901;-0.2765856;-2.799954;100.0230
25.92934;279.9758;1.751378;13.10772;-0.2782010;-2.817810;100.0814
25.99600;280.6414;1.749603;13.09585;-0.2798439;-2.835947;100.0174
26.06266;281.3068;1.747690;13.07444;-0.2819287;-2.858591;99.98163
26.12934;281.9688;1.745779;13.04522;-0.2843672;-2.884842;100.0299
26.19600;282.6266;1.743869;13.00424;-0.2873415;-2.916553;99.98066
26.26267;283.2930;1.741771;12.95920;-0.2905030;-2.950194;100.0237
26.32934;283.9536;1.739595;12.90328;-0.2941547;-2.988858;99.98719
26.39600;284.6162;1.737232;12.83666;-0.2982924;-3.032496;99.97369
26.46267;285.2764;1.734816;12.76021;-0.3028684;-3.080633;99.98710
26.52934;285.9397;1.732352;12.66888;-0.3081213;-3.135711;99.98106
26.59600;286.6014;1.729579;12.56220;-0.3140650;-3.197879;100.0062
26.66266;287.2617;1.726762;12.44984;-0.3202476;-3.262540;99.95793
26.72934;287.9192;1.723876;12.32186;-0.3271250;-3.334344;100.0131
26.79600;288.5771;1.720740;12.17953;-0.3346396;-3.412722;99.97899
26.86267;289.2390;1.717392;12.02696;-0.3426029;-3.495756;100.0599
26.92934;289.8994;1.713766;11.86178;-0.3511156;-3.584490;99.99859
26.99600;290.5578;1.709948;11.68897;-0.3599456;-3.676550;100.0236
27.06266;291.2116;1.706094;11.50653;-0.3691794;-3.772822;100.0385
27.12934;291.8714;1.701886;11.31933;-0.3786050;-3.871161;100.0140
27.19600;292.5298;1.697395;11.12348;-0.3883911;-3.973289;100.0013
27.26267;293.1813;1.692734;10.92377;-0.3983105;-4.076872;99.99328
27.32934;293.8418;1.687728;10.71863;-0.4084509;-4.182829;99.98481
27.39600;294.4958;1.682399;10.50927;-0.4187426;-4.290450;100.0019
27.46267;295.1530;1.676750;10.30016;-0.4289887;-4.397700;99.95614
27.52934;295.8044;1.670868;10.08705;-0.4393754;-4.506504;100.0314
27.59600;296.4647;1.664794;9.875003;-0.4496856;-4.614633;100.0491
27.66266;297.1230;1.658161;9.670770;-0.4596076;-4.718896;100.0416
27.72934;297.7785;1.651240;9.467506;-0.4694486;-4.822424;100.0078
27.79600;298.4372;1.643928;9.266590;-0.4791528;-4.924652;99.89711
27.86267;299.0951;1.636342;9.084598;-0.4879764;-5.017922;99.98829
27.92934;299.7566;1.628218;8.908585;-0.4965160;-5.108252;99.98851
27.99600;300.4150;1.619524;8.734194;-0.5049563;-5.197609;99.97472
28.06266;301.0774;1.610154;8.571320;-0.5128567;-5.281484;99.95938
28.12934;301.7394;1.600221;8.404418;-0.5209091;-5.367005;100.0727
28.19600;302.3994;1.589320;8.218618;-0.5297728;-5.460969;99.98422
28.26267;303.0600;1.577093;8.033960;-0.5385569;-5.554213;100.0005
28.32934;303.7176;1.563785;7.825568;-0.5483593;-5.658033;99.98341
28.39600;304.3808;1.549501;7.605626;-0.5586433;-5.766926;100.0426
28.46267;305.0498;1.533422;7.465078;-0.5653921;-5.839431;99.98686
28.52934;305.7055;1.515852;7.329068;-0.5719091;-5.909606;100.0243
28.59600;306.3649;1.499882;7.161090;-0.5798125;-5.994150;100.0121
28.66266;307.0246;1.484688;7.067011;-0.5844433;-6.044934;99.99407
28.72934;307.6907;1.469610;6.992922;-0.5881858;-6.086592;100.0224
28.79600;308.3538;1.454566;6.948216;-0.5906270;-6.114807;99.98293
28.86267;309.0156;1.440056;6.906868;-0.5929123;-6.141438;100.0072
28.92934;309.6791;1.425704;6.870944;-0.5949536;-6.165551;99.97250
28.99600;310.3432;1.411474;6.849744;-0.5963472;-6.182988;99.99431
29.06266;311.0065;1.397587;6.827876;-0.5977642;-6.200676;100.0045
29.12934;311.6692;1.383828;6.816524;-0.5987195;-6.213590;100.0545
29.19600;312.3346;1.370597;6.814343;-0.5992745;-6.222340;100.0166
29.26267;312.9982;1.357638;6.822310;-0.5993880;-6.226529;99.97382
29.32934;313.6606;1.344965;6.838592;-0.5991406;-6.226960;100.0117
29.39600;314.3276;1.332517;6.877665;-0.5979135;-6.217200;99.95356
29.46267;314.9942;1.320488;6.975989;-0.5941390;-6.180943;99.98705
29.52934;315.6614;1.308688;7.032930;-0.5921559;-6.163296;100.0120
29.59600;316.3288;1.297250;7.076495;-0.5907535;-6.151670;99.98081
29.66266;316.9885;1.286152;7.119976;-0.5893550;-6.140070;100.0246
29.72934;317.6593;1.275184;7.155585;-0.5883038;-6.132075;100.0223
29.79600;318.3229;1.264468;7.188910;-0.5873500;-6.125105;99.97528
29.86267;319.0018;1.254041;7.219718;-0.5865154;-6.119346;99.98214
29.92934;319.6686;1.243868;7.252048;-0.5856250;-6.112891;100.0379
29.99600;320.3328;1.234110;7.282095;-0.5848396;-6.107434;100.0157
30.06266;321.0015;1.224620;7.314957;-0.5839395;-6.100772;99.98028
30.12934;321.6698;1.215282;7.343580;-0.5832222;-6.096020;100.0029
30.19600;322.3369;1.206356;7.375669;-0.5823597;-6.089726;99.97992
30.26267;323.0025;1.197930;7.403572;-0.5816761;-6.085301;100.0454
30.32934;323.6655;1.189638;7.431434;-0.5809950;-6.080891;100.0353
30.39600;324.3388;1.181689;7.457293;-0.5804062;-6.077441;100.0197
30.46267;325.0029;1.174057;7.486616;-0.5796699;-6.072458;99.95919
30.52934;325.6714;1.166766;7.511782;-0.5791122;-6.069326;100.0344
30.59600;326.3443;1.159651;7.536505;-0.5785781;-6.066448;100.0511
30.66266;327.0076;1.152804;7.563734;-0.5779362;-6.062438;99.99405
30.72934;327.6812;1.146273;7.588810;-0.5773920;-6.059440;99.96591
30.79600;328.3472;1.139977;7.622968;-0.5764674;-6.052441;99.97405
30.86267;329.0146;1.134004;7.657294;-0.5755393;-6.045393;99.96232
30.92934;329.6816;1.128174;7.689726;-0.5746939;-6.039219;100.0484
30.99600;330.3542;1.122874;7.726379;-0.5736793;-6.031250;100.0207
31.06266;331.0224;1.117801;7.762362;-0.5726934;-6.023568;99.97300
31.12934;331.6878;1.112840;7.797832;-0.5717315;-6.016137;100.0030
31.19600;332.3552;1.108092;7.825062;-0.5711137;-6.012310;100.0010
31.26267;333.0242;1.103539;7.854892;-0.5703930;-6.007405;100.0280
31.32934;333.6948;1.099473;7.880141;-0.5698643;-6.004514;100.0180
31.39600;334.3576;1.095308;7.906819;-0.5692746;-6.000967;99.99049
31.46267;335.0243;1.091478;7.926081;-0.5689934;-6.000666;100.0205
31.52934;335.6950;1.087771;7.946284;-0.5686778;-5.999997;100.0143
31.59600;336.3617;1.084311;7.967575;-0.5683174;-5.998863;100.0005
31.66266;337.0276;1.081049;7.977582;-0.5684184;-6.002588;99.97945
31.72934;337.6937;1.077972;7.988561;-0.5684807;-6.005906;99.99686
31.79600;338.3551;1.074998;7.999622;-0.5685371;-6.009155;99.92652
31.86267;339.0234;1.072139;8.003468;-0.5688918;-6.015552;100.0309
31.92934;339.6914;1.069530;8.008434;-0.5692094;-6.021485;99.98938
31.99600;340.3540;1.066966;8.011262;-0.5696144;-6.028293;99.99035
32.06267;341.0268;1.064611;8.011116;-0.5701450;-6.036430;100.0079
32.12934;341.6924;1.062510;8.010344;-0.5706968;-6.044812;100.0415
32.19600;342.3513;1.060437;8.003600;-0.5714842;-6.055682;99.96642
32.26266;343.0220;1.058395;7.996522;-0.5722896;-6.066746;99.99735
32.32934;343.6845;1.056535;7.986166;-0.5732215;-6.079163;99.96064
32.39600;344.3503;1.054848;7.972431;-0.5742886;-6.093021;100.0264
32.46266;345.0169;1.053148;7.956235;-0.5754524;-6.107912;99.98719
32.52934;345.6778;1.051568;7.936813;-0.5767399;-6.124136;100.0430
32.59600;346.3442;1.050006;7.916466;-0.5780639;-6.140748;99.96236
32.66266;347.0041;1.048570;7.894729;-0.5794368;-6.157890;99.99762
32.72934;347.6710;1.047108;7.866368;-0.5810740;-6.177856;100.0127
32.79600;348.3416;1.045888;7.844626;-0.5824472;-6.195041;100.0122
32.86267;349.0036;1.044748;7.811590;-0.5842606;-6.216920;100.0191
32.92933;349.6675;1.043652;7.779136;-0.5860470;-6.238511;100.0123
32.99600;350.3387;1.042516;7.750278;-0.5876910;-6.258609;100.0502
33.06267;350.9912;1.041336;7.716157;-0.5895292;-6.280793;100.0099
33.12933;351.6635;1.040322;7.679399;-0.5914766;-6.304143;99.98032
33.19600;352.3291;1.039310;7.639702;-0.5935330;-6.328689;99.96851
33.26266;352.9911;1.038325;7.598466;-0.5956432;-6.353839;99.98360
33.32933;353.6584;1.037443;7.554990;-0.5978382;-6.379894;99.97022
33.39600;354.3157;1.036656;7.512504;-0.5999840;-6.405443;100.0100
33.46266;354.9874;1.035799;7.463484;-0.6023873;-6.433760;99.97875
33.52933;355.6475;1.035023;7.410239;-0.6049448;-6.463752;100.0051
33.59600;356.3120;1.034187;7.358064;-0.6074555;-6.493259;99.99024
33.66266;356.9791;1.033416;7.308611;-0.6098557;-6.521611;100.0428
33.72933;357.6439;1.032702;7.250731;-0.6125770;-6.553424;100.0210
33.79600;358.3078;1.032097;7.195720;-0.6151794;-6.583990;100.0051
33.86267;358.9675;1.031379;7.135522;-0.6179743;-6.616619;99.98332
33.92933;359.6337;1.030653;7.073929;-0.6208276;-6.649812;99.98982
33.99600;360.3028;1.029940;7.014026;-0.6236162;-6.682285;99.99952
34.06267;360.9636;1.029313;6.953126;-0.6264332;-6.715099;100.0542
34.12933;361.6300;1.028645;6.887876;-0.6294128;-6.749660;99.99269
34.19600;362.2945;1.028017;6.818993;-0.6325243;-6.785668;99.97976
34.26266;362.9568;1.027356;6.752472;-0.6355361;-6.820624;99.98599
34.32933;363.6181;1.026912;6.679322;-0.6387947;-6.858261;100.0094
34.39600;364.2804;1.026234;6.609036;-0.6419355;-6.894648;99.98679
34.46266;364.9453;1.025778;6.537016;-0.6451368;-6.931726;100.0143
34.52933;365.6075;1.025177;6.464963;-0.6483303;-6.968738;99.94830
34.59600;366.2709;1.024578;6.394446;-0.6514578;-7.005066;99.97704
34.66266;366.9319;1.023993;6.318016;-0.6548024;-7.043765;99.97931
34.72933;367.5953;1.023459;6.240458;-0.6581826;-7.082874;100.0474
34.79600;368.2608;1.022927;6.157980;-0.6617418;-7.123920;99.98082
34.86267;368.9237;1.022401;6.082715;-0.6650180;-7.161957;99.97387
34.92933;369.5844;1.021820;6.006300;-0.6683291;-7.200394;100.0074
34.99600;370.2474;1.021320;5.927557;-0.6717218;-7.239751;100.0351
35.06267;370.9100;1.020794;5.842613;-0.6753400;-7.281560;100.0212
35.12933;371.5668;1.020231;5.758086;-0.6789311;-7.323100;99.99556
35.19600;372.2290;1.019739;5.675828;-0.6824295;-7.363660;99.98250
35.26266;372.9024;1.019181;5.592571;-0.6859631;-7.404664;99.99566
35.32933;373.5662;1.018701;5.508591;-0.6895122;-7.445868;100.0376
35.39600;374.2270;1.018387;5.418891;-0.6932644;-7.489265;100.0273
35.46266;374.8860;1.017828;5.333965;-0.6968285;-7.530656;99.97034
35.52933;375.5506;1.017192;5.250463;-0.7003335;-7.571453;99.94899
35.59600;376.2126;1.016778;5.159268;-0.7041166;-7.615290;100.0137
35.66266;376.8744;1.016328;5.069306;-0.7078439;-7.658544;99.99219
35.72933;377.5346;1.015797;4.982542;-0.7114429;-7.700434;100.0252
35.79600;378.1978;1.015413;4.895500;-0.7150453;-7.742407;100.0065
35.86267;378.8643;1.014889;4.807548;-0.7186749;-7.784705;99.99053
35.92933;379.5268;1.014194;4.715689;-0.7224454;-7.828486;100.0095
35.99600;380.1868;1.013813;4.622378;-0.7262674;-7.872774;100.0186
36.06267;380.8532;1.013348;4.533576;-0.7299157;-7.915205;100.0395
36.12933;381.5180;1.012952;4.440719;-0.7337056;-7.959212;99.96209
36.19600;382.1760;1.012568;4.349231;-0.7374345;-8.002582;100.0283
36.26266;382.8388;1.011979;4.252891;-0.7413339;-8.047822;99.99674
36.32933;383.5030;1.011504;4.155904;-0.7452490;-8.093271;100.0198
36.39600;384.1642;1.011052;4.059859;-0.7491204;-8.138284;100.0342
36.46266;384.8302;1.010565;3.970005;-0.7527566;-8.180755;99.97195
36.52933;385.4889;1.010060;3.876279;-0.7565256;-8.224712;100.0456
36.59600;386.1570;1.009748;3.780009;-0.7603808;-8.269634;99.98738
36.66266;386.8162;1.009198;3.676430;-0.7644924;-8.317384;99.95750
36.72933;387.4843;1.008678;3.578516;-0.7683899;-8.362826;99.96168
36.79600;388.1440;1.008251;3.476975;-0.7724079;-8.409603;99.95486
36.86267;388.8059;1.007870;3.374102;-0.7764663;-8.456856;100.0216
36.92933;389.4681;1.007384;3.271668;-0.7804995;-8.503866;99.98450
36.99600;390.1282;1.006782;3.170860;-0.7844644;-8.550157;99.97642
37.06267;390.7933;1.006346;3.068034;-0.7884950;-8.597206;100.0178
37.12933;391.4505;1.005866;2.960542;-0.7926837;-8.646018;99.97548
37.19600;392.1182;1.005432;2.858198;-0.7966782;-8.692719;100.0020
37.26266;392.7762;1.005093;2.752287;-0.8007918;-8.740766;100.0642
37.32933;393.4378;1.004563;2.645090;-0.8049424;-8.789244;99.95343
37.39600;394.1003;1.004073;2.542396;-0.8089236;-8.835922;100.0180
37.46266;394.7652;1.003712;2.435808;-0.8130356;-8.884053;100.0476
37.52933;395.4264;1.003208;2.329438;-0.8171301;-8.932022;99.97569
37.59600;396.0926;1.002831;2.224153;-0.8211778;-8.979511;100.0306
37.66266;396.7539;1.002334;2.110917;-0.8255000;-9.030043;99.98121
37.72933;397.4145;1.001776;2.005470;-0.8295348;-9.077455;100.0539
37.79600;398.0784;1.001487;1.897011;-0.8336684;-9.125982;99.98844
37.86267;398.7356;1.000983;1.785750;-0.8378918;-9.175518;99.98378
37.92933;399.3975;1.000415;1.680232;-0.8419071;-9.222762;100.0113
37.99600;400.0628;1.000056;1.576990;-0.8458431;-9.269082;100.0182
38.06267;400.7252;0.9997172;1.465541;-0.8500616;-9.318530;100.0388
38.12933;401.3874;0.9994457;1.351052;-0.8543781;-9.369072;99.98501
38.19600;402.0494;0.9989493;1.240369;-0.8585516;-9.418087;100.0072
38.26266;402.7105;0.9983953;1.133417;-0.8625845;-9.465578;99.95470
38.32933;403.3766;0.9978982;1.025358;-0.8666493;-9.513468;99.99755
38.39600;404.0418;0.9975965;0.9124061;-0.8708772;-9.563176;100.0339
38.46266;404.7046;0.9971918;0.8002563;-0.8750680;-9.612505;99.98078
38.52933;405.3644;0.9966576;0.6875414;-0.8792694;-9.661972;100.0146
38.59600;406.0312;0.9963132;0.5673585;-0.8837235;-9.714264;100.0463
38.66266;406.6918;0.9959225;0.4551369;-0.8878906;-9.763425;100.0107
38.72933;407.3559;0.9955412;0.3387656;-0.8921930;-9.814106;100.0112
38.79600;408.0188;0.9949936;0.2236248;-0.8964444;-9.864264;99.98014
38.86267;408.6795;0.9945362;0.1036167;-0.9008559;-9.916210;99.97413
38.92933;409.3450;0.9941619;-.01870067;-0.9053382;-9.968969;100.0379
38.99600;410.0035;0.9939259;-0.1387432;-0.9097322;-10.02079;100.0100
39.06267;410.6672;0.9934653;-0.2579350;-0.9140874;-10.07221;100.0396
39.12933;411.3302;0.9930938;-0.3810165;-0.9185686;-10.12506;99.96371
39.19600;411.9951;0.9926732;-0.5019847;-0.9229684;-10.17706;100.0012
39.26266;412.6626;0.9922197;-0.6258277;-0.9274578;-10.23008;100.0170
39.32933;413.3190;0.9918959;-0.7525190;-0.9320351;-10.28409;99.99228
39.39600;413.9815;0.9917812;-0.8748220;-0.9364514;-10.33634;100.0638
39.46266;414.6437;0.9913390;-1.001522;-0.9410095;-10.39020;100.0168
39.52933;415.3094;0.9908166;-1.134227;-0.9457650;-10.44629;100.0117
39.59600;415.9660;0.9903595;-1.260027;-0.9502742;-10.49968;99.95812
39.66266;416.6282;0.9899399;-1.386108;-0.9547816;-10.55306;100.0220
39.72933;417.2872;0.9895819;-1.509874;-0.9592030;-10.60556;99.98131
39.79600;417.9482;0.9892399;-1.639455;-0.9638124;-10.66015;100.0207
39.86267;418.6156;0.9890644;-1.766404;-0.9683226;-10.71369;99.93579
39.92933;419.2730;0.9886914;-1.896984;-0.9729512;-10.76856;100.0290
39.99600;419.9367;0.9883026;-2.021558;-0.9773700;-10.82106;99.95176
40.06267;420.6003;0.9879524;-2.153973;-0.9820480;-10.87646;99.98501
40.12933;421.2579;0.9876840;-2.279760;-0.9864924;-10.92930;100.0087
40.19600;421.9238;0.9873241;-2.410555;-0.9910957;-10.98393;99.99063
40.26266;422.5846;0.9868984;-2.541194;-0.9956866;-11.03848;99.95142
40.32933;423.2460;0.9865241;-2.675137;-1.000379;-11.09416;99.98102
40.39600;423.9117;0.9862606;-2.802788;-1.004849;-11.14742;99.94551
40.46266;424.5719;0.9858672;-2.933272;-1.009406;-11.20168;99.97792
40.52933;425.2292;0.9855454;-3.066915;-1.014061;-11.25707;100.0489
40.59600;425.8952;0.9852298;-3.200001;-1.018686;-11.31215;100.0014
40.66266;426.5569;0.9849922;-3.338594;-1.023489;-11.36925;99.97769
40.72933;427.2191;0.9846994;-3.479656;-1.028362;-11.42716;99.96922
40.79600;427.8833;0.9844191;-3.613788;-1.032995;-11.48242;100.0142
40.86267;428.5440;0.9841254;-3.754610;-1.037842;-11.54011;100.0341
40.92933;429.2047;0.9837582;-3.898936;-1.042795;-11.59900;100.0237
40.99600;429.8662;0.9834629;-4.041010;-1.047662;-11.65698;99.93788
41.06266;430.5296;0.9833563;-4.185119;-1.052589;-11.71566;100.0170
41.12934;431.1886;0.9829982;-4.324070;-1.057334;-11.77235;99.98186
41.19600;431.8556;0.9825906;-4.464680;-1.062124;-11.82959;99.98766
41.26266;432.5150;0.9823554;-4.612408;-1.067142;-11.88940;99.99835
41.32934;433.1750;0.9820790;-4.755590;-1.071999;-11.94745;99.98975
41.39600;433.8410;0.9818264;-4.905536;-1.077068;-12.00789;99.99559
41.46266;434.5042;0.9816303;-5.055576;-1.082131;-12.06832;99.96538
41.52934;435.1620;0.9813697;-5.204293;-1.087140;-12.12816;99.96722
41.59600;435.8257;0.9811488;-5.350996;-1.092073;-12.18720;99.97311
41.66266;436.4853;0.9809610;-5.505419;-1.097250;-12.24899;99.99116
41.72934;437.1462;0.9805772;-5.655621;-1.102277;-12.30915;99.99316
41.79600;437.8076;0.9803009;-5.811230;-1.107470;-12.37119;100.0053
41.86266;438.4718;0.9801309;-5.966414;-1.112640;-12.43304;100.0371
41.92934;439.1280;0.9798562;-6.114990;-1.117588;-12.49242;100.0264
41.99600;439.7903;0.9796418;-6.265078;-1.122581;-12.55221;100.0184
42.06266;440.4562;0.9793178;-6.423938;-1.127854;-12.61515;100.0148
42.12934;441.1110;0.9791444;-6.581628;-1.133081;-12.67762;99.99503
42.19600;441.7737;0.9790754;-6.734079;-1.138125;-12.73806;100.0428
42.26266;442.4346;0.9788374;-6.890284;-1.143281;-12.79979;100.0368
42.32934;443.0986;0.9785205;-7.048369;-1.148487;-12.86212;99.99903
42.39600;443.7575;0.9783686;-7.201505;-1.153526;-12.92263;99.97719
42.46266;444.4170;0.9780768;-7.359463;-1.158709;-12.98476;100.0618
42.52934;445.0750;0.9778838;-7.515064;-1.163807;-13.04599;99.98281
42.59600;445.7383;0.9776851;-7.666684;-1.168765;-13.10569;99.99168
42.66266;446.3950;0.9774493;-7.823209;-1.173875;-13.16712;100.0110
42.72934;447.0580;0.9772326;-7.980469;-1.178994;-13.22869;100.0290
42.79600;447.7200;0.9770226;-8.137116;-1.184087;-13.29000;99.98918
42.86266;448.3832;0.9767424;-8.291550;-1.189098;-13.35046;99.97856
42.92934;449.0459;0.9765402;-8.440921;-1.193940;-13.40904;99.97330
42.99600;449.7082;0.9764408;-8.601828;-1.199139;-13.47166;100.0341
43.06266;450.3656;0.9762589;-8.762958;-1.204336;-13.53429;100.0372
43.12934;451.0292;0.9760945;-8.924309;-1.209529;-13.59690;100.0311
43.19600;451.6924;0.9758828;-9.082138;-1.214601;-13.65821;100.0312
43.26266;452.3549;0.9757297;-9.246515;-1.219872;-13.72180;100.0339
43.32934;453.0171;0.9755572;-9.410606;-1.225124;-13.78519;99.95759
43.39600;453.6797;0.9753316;-9.571522;-1.230265;-13.84739;99.94966
43.46266;454.3398;0.9751856;-9.740768;-1.235661;-13.91249;100.0128
43.52934;455.0010;0.9750731;-9.909326;-1.241024;-13.97724;99.99859
43.59600;455.6588;0.9747968;-10.07938;-1.246425;-14.04246;99.98710
43.66266;456.3178;0.9746872;-10.24264;-1.251602;-14.10520;100.0202
43.72934;456.9817;0.9745728;-10.40964;-1.256884;-14.16914;100.0209
43.79600;457.6469;0.9744691;-10.58100;-1.262293;-14.23458;99.97920
43.86266;458.3076;0.9742389;-10.75378;-1.267739;-14.30046;100.0060
43.92934;458.9700;0.9739962;-10.92605;-1.273159;-14.36610;99.99676
43.99600;459.6285;0.9738816;-11.10123;-1.278667;-14.43268;100.0163
44.06266;460.2924;0.9737478;-11.27481;-1.284117;-14.49859;100.0171
44.12934;460.9475;0.9734374;-11.45013;-1.289616;-14.56508;100.0289
44.19600;461.6070;0.9735376;-11.62431;-1.295065;-14.63104;100.0069
44.26266;462.2672;0.9734064;-11.79888;-1.300518;-14.69708;99.97559
44.32934;462.9313;0.9733826;-11.97728;-1.306077;-14.76436;99.99887
44.39600;463.5920;0.9729705;-12.15522;-1.311615;-14.83146;99.99844
44.46266;464.2490;0.9728012;-12.33531;-1.317210;-14.89923;100.0644
44.52934;464.9139;0.9728158;-12.50854;-1.322579;-14.96447;99.91301
44.59600;465.5742;0.9726284;-12.68741;-1.328114;-15.03165;100.0176
44.66266;466.2347;0.9723776;-12.86740;-1.333676;-15.09916;99.98975
44.72934;466.8955;0.9722731;-13.04502;-1.339154;-15.16578;100.0383
44.79600;467.5594;0.9721688;-13.22520;-1.344697;-15.23314;100.0036
44.86266;468.2174;0.9719179;-13.40982;-1.350372;-15.30204;99.99924
44.92934;468.8828;0.9717306;-13.59086;-1.355921;-15.36956;100.0077
44.99600;469.5371;0.9718538;-13.77358;-1.361518;-15.43766;99.98972
45.06266;470.2010;0.9716022;-13.95511;-1.367064;-15.50521;100.0251
45.12934;470.8648;0.9714700;-14.14631;-1.372896;-15.57608;100.0096
45.19600;471.5170;0.9713461;-14.33825;-1.378746;-15.64715;100.0113
45.26266;472.1817;0.9711707;-14.52602;-1.384449;-15.71659;100.0013
45.32934;472.8422;0.9712110;-14.71082;-1.390056;-15.78500;100.0141
45.39600;473.5081;0.9709359;-14.89589;-1.395657;-15.85336;99.95670
45.46266;474.1658;0.9708351;-15.08678;-1.401431;-15.92376;99.96381
45.52934;474.8300;0.9706880;-15.28048;-1.407276;-15.99498;99.97909
45.59600;475.4809;0.9706036;-15.47110;-1.413026;-16.06517;100.0191
45.66266;476.1444;0.9703941;-15.66091;-1.418731;-16.13485;99.96539
45.72934;476.8082;0.9703634;-15.85341;-1.424509;-16.20544;100.0167
45.79600;477.4670;0.9702651;-16.04806;-1.430344;-16.27672;100.0360
45.86266;478.1268;0.9701124;-16.24490;-1.436235;-16.34867;100.0040
45.92934;478.7867;0.9699318;-16.44216;-1.442126;-16.42064;100.0653
45.99600;479.4507;0.9698322;-16.63932;-1.448005;-16.49252;99.98718
46.06266;480.1122;0.9696912;-16.83284;-1.453769;-16.56310;100.0112
46.12934;480.7697;0.9695663;-17.03092;-1.459661;-16.63516;100.0121
46.19600;481.4309;0.9695278;-17.22781;-1.465503;-16.70668;99.98926
46.26266;482.0902;0.9693306;-17.42603;-1.471377;-16.77862;99.99644
46.32934;482.7496;0.9692602;-17.62568;-1.477284;-16.85098;99.95497
46.39600;483.4084;0.9692380;-17.82543;-1.483184;-16.92328;99.98728
46.46266;484.0640;0.9690629;-18.02550;-1.489086;-16.99566;99.96316
46.52934;484.7278;0.9690459;-18.22264;-1.494883;-17.06687;99.99524
46.59600;485.3912;0.9687774;-18.41884;-1.500644;-17.13773;100.0259
46.66266;486.0545;0.9686059;-18.61778;-1.506478;-17.20947;100.0358
46.72934;486.7128;0.9685936;-18.82479;-1.512544;-17.28388;99.97144
46.79600;487.3717;0.9684872;-19.02766;-1.518477;-17.35683;99.95960
46.86266;488.0351;0.9684830;-19.23456;-1.524516;-17.43102;99.96172
46.92934;488.6966;0.9683470;-19.44117;-1.530536;-17.50503;99.99450
46.99600;489.3594;0.9681866;-19.64349;-1.536418;-17.57749;99.99924
47.06266;490.0186;0.9681171;-19.85134;-1.542456;-17.65180;100.0314
47.12934;490.6750;0.9681094;-20.06889;-1.548772;-17.72931;99.99258
47.19600;491.3378;0.9678444;-20.27748;-1.554808;-17.80367;100.0410
47.26266;491.9982;0.9676871;-20.49282;-1.561035;-17.88026;99.99624
47.32934;492.6604;0.9677025;-20.70085;-1.567035;-17.95428;99.98074
47.39600;493.3160;0.9675582;-20.91381;-1.573173;-18.02990;100.0233
47.46266;493.9798;0.9674431;-21.13316;-1.579483;-18.10758;100.0051
47.52934;494.6396;0.9673110;-21.34870;-1.585674;-18.18391;100.0128
47.59600;495.2980;0.9672639;-21.56402;-1.591848;-18.26008;100.0049
47.66266;495.9585;0.9671055;-21.77703;-1.597943;-18.33541;100.0027
47.72934;496.6175;0.9670532;-21.99228;-1.604094;-18.41142;100.0045
47.79600;497.2746;0.9669937;-22.20856;-1.610266;-18.48767;99.98686
47.86266;497.9416;0.9668394;-22.42505;-1.616428;-18.56391;99.98241
47.92934;498.6017;0.9667441;-22.64582;-1.622708;-18.64154;99.97710
47.99600;499.2619;0.9666366;-22.86357;-1.628891;-18.71806;100.0581
48.06266;499.9160;0.9665832;-23.08239;-1.635102;-18.79489;100.0316
48.12934;500.5781;0.9665234;-23.30367;-1.641368;-18.87240;99.97031
48.19600;501.2425;0.9664601;-23.51357;-1.647294;-18.94605;100.0508
48.26266;501.9016;0.9662695;-23.73761;-1.653624;-19.02440;99.94856
48.32100;502.4806;0.9661461;-23.92567;-1.658924;-19.09024;99.98545